Workbook

Sheet Resumo
B2: Oferta/Cargo | C2: Gênero | G2: Qt. Total
C3: Feminino | E3: Masculino
C4: Qt. | D4: % | E4: Qt. | F4: %
B5: PCPE - Cargo 01: Agente de Policia - 2025.2 | C5: =COUNTIFS(Matriculados!A:A,B5,Matriculados!M:M,"f") -> 72 | D5: =ROUND((C5*100)/$G5,1) -> 27.9 | E5: =COUNTIFS(Matriculados!A:A,B5,Matriculados!M:M,"m") -> 186 | F5: =ROUND((E5*100)/$G5,1) -> 72.1 | G5: =SUM(C5,E5) -> 258
B6: PCPE - Cargo 01: Agente de Policia - 2025.2 (SUBJUD) | C6: =COUNTIFS(Matriculados!A:A,B6,Matriculados!M:M,"f") -> 0 | D6: =ROUND((C6*100)/$G6,1) -> 0 | E6: =COUNTIFS(Matriculados!A:A,B6,Matriculados!M:M,"m") -> 1 | F6: =ROUND((E6*100)/$G6,1) -> 100 | G6: =SUM(C6,E6) -> 1
B7: PCPE - Cargo 01: Agente de Policia - 2025.2 (SUBJUD 2016) | C7: =COUNTIFS(Matriculados!A:A,B7,Matriculados!M:M,"f") -> 0 | D7: =ROUND((C7*100)/$G7,1) -> #DIV/0! | E7: =COUNTIFS(Matriculados!A:A,B7,Matriculados!M:M,"m") -> 0 | F7: =ROUND((E7*100)/$G7,1) -> #DIV/0! | G7: =SUM(C7,E7) -> 0
B8: PCPE - Cargo 02: Delegado de Policia - 2025.2 | C8: =COUNTIFS(Matriculados!A:A,B8,Matriculados!M:M,"f") -> 19 | D8: =ROUND((C8*100)/$G8,1) -> 48.7 | E8: =COUNTIFS(Matriculados!A:A,B8,Matriculados!M:M,"m") -> 20 | F8: =ROUND((E8*100)/$G8,1) -> 51.3 | G8: =SUM(C8,E8) -> 39
B9: PCPE - Cargo 02: Delegado de Policia - 2025.2 (SUBJUD) | C9: =COUNTIFS(Matriculados!A:A,B9,Matriculados!M:M,"f") -> 2 | D9: =ROUND((C9*100)/$G9,1) -> 50 | E9: =COUNTIFS(Matriculados!A:A,B9,Matriculados!M:M,"m") -> 2 | F9: =ROUND((E9*100)/$G9,1) -> 50 | G9: =SUM(C9,E9) -> 4
B10: PCPE - Cargo 03: Escrivao de Policia - 2025.2 | C10: =COUNTIFS(Matriculados!A:A,B10,Matriculados!M:M,"f") -> 72 | D10: =ROUND((C10*100)/$G10,1) -> 50.3 | E10: =COUNTIFS(Matriculados!A:A,B10,Matriculados!M:M,"m") -> 71 | F10: =ROUND((E10*100)/$G10,1) -> 49.7 | G10: =SUM(C10,E10) -> 143
B11: PCPE - Cargo 03: Escrivao de Policia - 2025.2 (SUBJUD) | C11: =COUNTIFS(Matriculados!A:A,B11,Matriculados!M:M,"f") -> 1 | D11: =ROUND((C11*100)/$G11,1) -> 50 | E11: =COUNTIFS(Matriculados!A:A,B11,Matriculados!M:M,"m") -> 1 | F11: =ROUND((E11*100)/$G11,1) -> 50 | G11: =SUM(C11,E11) -> 2
B12: Total | C12: =SUM(C5:C11) -> 166 | D12: =ROUND((C12*100)/$G12,1) -> 37.1 | E12: =SUM(E5:E11) -> 281 | F12: =ROUND((E12*100)/$G12,1) -> 62.9 | G12: =SUM(C12,E12) -> 447
B13: Matrículas efetuadas entre 17/11/2025 e 05/12/2025
B14: Dados extraídos em 06/12/2025 15:17

Sheet Matriculados
A1: nome_oferta | B1: nome_turma | C1: codg_matricula | D1: data_matricula | E1: numr_inscricao_origem | F1: nome_pessoa | G1: lateralidade_manual | H1: indc_convocacao_pne | I1: nome_necessidades_especiais_permanentes | J1: indc_religiao_guardasabados | K1: numr_cpf | L1: numr_fone_1 | M1: codg_sexo | N1: numr_rg | O1: data_exped_rg | P1: sigl_orgao_exped_rg | Q1: email | R1: cpf corrigido | S1: DOMINIO
A2: PCPE - Cargo 01: Agente de Policia - 2025.2 | B2: AP-01-2025.2 | C2: 2228 | D2: 2025-11-17 | E2: 10025304 | F2: ABDIAS FERREIRA LEMOS JUNIOR | G2: Destro | H2: 0 | J2: 0 | K2: 12697608400 | L2: 87981138737 | M2: m | N2: 9995369 | O2: 18092024 | P2: SDS/PE | Q2: abdias.lemos@policiacivil.pe.gov.br | R2: 12697608400 | S2: PCPE
A3: PCPE - Cargo 01: Agente de Policia - 2025.2 | B3: AP-07-2025.2 | C3: 2292 | D3: 2025-11-17 | E3: 10014573 | F3: ADELSON DANTAS COSTA SOBRINHO | G3: Canhoto | H3: 0 | J3: 0 | K3: 1355555400 | L3: 81981293075 | M3: m | N3: 6964101 | O3: 03062009 | P3: PE | Q3: adelson.costa@policiacivil.pe.gov.br | R3: 01355555400 | S3: PCPE
A4: PCPE - Cargo 01: Agente de Policia - 2025.2 | B4: AP-08-2025.2 | C4: 2209 | D4: 2025-11-17 | E4: 10028429 | F4: ADRIANO NUNES TAVARES | G4: Destro | H4: 0 | J4: 0 | K4: 89975758215 | L4: 91982815052 | M4: m | N4: 4982054 | O4: 17112015 | P4: PA | Q4: adriano.tavares@policiacivil.pe.gov.br | R4: 89975758215 | S4: PCPE
A5: PCPE - Cargo 01: Agente de Policia - 2025.2 | B5: AP-05-2025.2 | C5: 2220 | D5: 2025-11-17 | E5: 10064401 | F5: ADSON PEREIRA DE OLIVEIRA | G5: Destro | H5: 0 | J5: 0 | K5: 9806110404 | L5: 81995252737 | M5: m | N5: 59343 | O5: 01102025 | P5: PMPE | Q5: adson.oliveira@pm.pe.gov.br | R5: 09806110404 | S5: PM
A6: PCPE - Cargo 01: Agente de Policia - 2025.2 | B6: AP-07-2025.2 | C6: 2094 | D6: 2025-11-17 | E6: 10022273 | F6: AIANY MARIA QUEIROZ FELIX | G6: Destro | H6: 0 | J6: 0 | K6: 10435102494 | L6: 81995717781 | M6: f | N6: 8501126 | O6: 13082018 | P6: PE | Q6: aiany.felix@policiacivil.pe.gov.br | R6: 10435102494 | S6: PCPE
A7: PCPE - Cargo 01: Agente de Policia - 2025.2 | B7: AP-08-2025.2 | C7: 2478 | D7: 2025-11-24 | E7: 10024960 | F7: AIRTON ROBERTO PEREIRA SIQUEIRA | G7: Destro | H7: 0 | J7: 0 | K7: 10541112430 | L7: 87988063890 | M7: m | N7: 8964070 | O7: 10032010 | P7: PE | Q7: airton.siqueira@pm.pe.gov.br | R7: 10541112430 | S7: PM
A8: PCPE - Cargo 01: Agente de Policia - 2025.2 | B8: AP-08-2025.2 | C8: 2132 | D8: 2025-11-17 | E8: 10054412 | F8: ALANA CARVALHO DE AZEVEDO REGIS | G8: Destro | H8: 0 | J8: 0 | K8: 11156477417 | L8: 8199996242 | M8: f | N8: 8753660 | O8: 24022021 | P8: PE | Q8: alana.regis@policiacivil.pe.gov.br | R8: 11156477417 | S8: PCPE
A9: PCPE - Cargo 01: Agente de Policia - 2025.2 | B9: AP-07-2025.2 | C9: 2518 | D9: 2025-12-04 | E9: 10010675 | F9: ALAYSE THAYANE DE OLIVEIRA BARROS | G9: Destro | H9: 0 | J9: 0 | K9: 9024447437 | L9: 82996071772 | M9: f | N9: 9024447437 | O9: 21112025 | P9: AL | Q9: alayse.barros@policiacivil.pe.gov.br | R9: 09024447437 | S9: PCPE
A10: PCPE - Cargo 01: Agente de Policia - 2025.2 | B10: AP-05-2025.2 | C10: 2128 | D10: 2025-11-17 | E10: 10049421 | F10: ALBERTY MICAEL NOIA DOS SANTOS | G10: Destro | H10: 0 | J10: 0 | K10: 12210556406 | L10: 82996952125 | M10: m | N10: 323172502 | O10: 11022016 | P10: RJ | Q10: alberty.santos@policiacivil.pe.gov.br | R10: 12210556406 | S10: PCPE
A11: PCPE - Cargo 01: Agente de Policia - 2025.2 | B11: AP-03-2025.2 | C11: 2386 | D11: 2025-11-18 | E11: 10035727 | F11: ALERVSON JOSE DA SILVA | G11: Destro | H11: 0 | J11: 0 | K11: 12171798440 | L11: 81993711319 | M11: m | N11: 8730408 | O11: 18042024 | P11: PE | Q11: alervson.silva@pm.pe.gov.br | R11: 12171798440 | S11: PM
A12: PCPE - Cargo 01: Agente de Policia - 2025.2 | B12: AP-01-2025.2 | C12: 2074 | D12: 2025-11-17 | E12: 10023305 | F12: ALEXANDRE SARAIVA CARNIATO | G12: Destro | H12: 0 | J12: 0 | K12: 769651470 | L12: 83991087175 | M12: m | N12: 1629751 | O12: 09082023 | P12: PB | Q12: alexandre.carniato@policiacivil.pe.gov.br | R12: 00769651470 | S12: PCPE
A13: PCPE - Cargo 01: Agente de Policia - 2025.2 | B13: AP-04-2025.2 | C13: 2148 | D13: 2025-11-17 | E13: 10006557 | F13: ALICE BASTOS MAZZOLA | G13: Destro | H13: 0 | J13: 0 | K13: 13059417482 | L13: 81995095136 | M13: f | N13: 10069860 | O13: 25092025 | P13: SDS/PE | Q13: alice.mazzola@policiacivil.pe.gov.br | R13: 13059417482 | S13: PCPE
A14: PCPE - Cargo 01: Agente de Policia - 2025.2 | B14: AP-02-2025.2 | C14: 2097 | D14: 2025-11-17 | E14: 10010274 | F14: ALISSON MOURA GOMES | G14: Destro | H14: 0 | J14: 0 | K14: 70165183454 | L14: 83982044369 | M14: m | N14: 4023538 | O14: 20012012 | P14: PB | Q14: alisson.gomes@policiacivil.pe.gov.br | R14: 70165183454 | S14: PCPE
A15: PCPE - Cargo 01: Agente de Policia - 2025.2 | B15: AP-06-2025.2 | C15: 2293 | D15: 2025-11-17 | E15: 10060432 | F15: ALISSON RICARDO COSTA SANTOS | G15: Destro | H15: 0 | J15: 0 | K15: 5611798594 | L15: 79991066472 | M15: m | N15: 34844783 | O15: 12022014 | P15: SE | Q15: alisson.rcs@policiacivil.pe.gov.br | R15: 05611798594 | S15: PCPE
A16: PCPE - Cargo 01: Agente de Policia - 2025.2 | B16: AP-05-2025.2 | C16: 2079 | D16: 2025-11-17 | E16: 10020824 | F16: ALLANA NASCIMENTO SILVA | G16: Destro | H16: 0 | J16: 0 | K16: 11162269448 | L16: 81992808986 | M16: f | N16: 9228555 | O16: 02062011 | P16: PE | Q16: allana.nascimento@policiacivil.pe.gov.br | R16: 11162269448 | S16: PCPE
A17: PCPE - Cargo 01: Agente de Policia - 2025.2 | B17: AP-05-2025.2 | C17: 2334 | D17: 2025-11-17 | E17: 10026753 | F17: ALLYSON ANDRADE FERREIRA | G17: Destro | H17: 0 | J17: 0 | K17: 12018068440 | L17: 81997181407 | M17: m | N17: 9623010 | O17: 18122012 | P17: SDS/PE | Q17: allyson.aferreira@pm.pe.gov.br | R17: 12018068440 | S17: PM
A18: PCPE - Cargo 01: Agente de Policia - 2025.2 | B18: AP-05-2025.2 | C18: 2162 | D18: 2025-11-17 | E18: 10022903 | F18: ALLYSSON ROMILDO SIQUEIRA FALCAO | G18: Destro | H18: 0 | J18: 0 | K18: 70860425444 | L18: 87996123369 | M18: m | N18: 9362048 | O18: 22022022 | P18: SDS-PE | Q18: allysson.falcao@policiacivil.pe.gov.br | R18: 70860425444 | S18: PCPE
A19: PCPE - Cargo 01: Agente de Policia - 2025.2 | B19: AP-07-2025.2 | C19: 2360 | D19: 2025-11-17 | E19: 10067846 | F19: ALVARO PEREIRA DOS SANTOS | G19: Destro | H19: 0 | J19: 0 | K19: 9493095401 | L19: 81995146406 | M19: m | N19: 8282414 | O19: 07052007 | P19: PE | Q19: alvaro.pereira@policiacivil.pe.gov.br | R19: 09493095401 | S19: PCPE
A20: PCPE - Cargo 01: Agente de Policia - 2025.2 | B20: AP-03-2025.2 | C20: 2037 | D20: 2025-11-17 | E20: 10020715 | F20: ALYNE MANUELA DE SOUZA FLORENCIO | G20: Canhoto | H20: 0 | J20: 0 | K20: 9717938407 | L20: 81994704120 | M20: f | N20: 8594315 | O20: 05082008 | P20: SDS/PE | Q20: alyne.florencio@pm.pe.gov.br | R20: 09717938407 | S20: PM
A21: PCPE - Cargo 01: Agente de Policia - 2025.2 | B21: AP-02-2025.2 | C21: 2260 | D21: 2025-11-17 | E21: 10003730 | F21: ALYSSON GOMES MARQUES | G21: Destro | H21: 0 | J21: 0 | K21: 11565204441 | L21: 87996619031 | M21: m | N21: 9419594 | O21: 10112023 | P21: PE | Q21: alysson.marques@policiacivil.pe.gov.br | R21: 11565204441 | S21: PCPE
A22: PCPE - Cargo 01: Agente de Policia - 2025.2 | B22: AP-08-2025.2 | C22: 2500 | D22: 2025-11-28 | E22: 10052591 | F22: AMANDA GOMES DE SOUSA AMORIM | G22: Destro | H22: 0 | J22: 0 | K22: 5739248485 | L22: 83996337207 | M22: f | N22: 2664443 | O22: 19082019 | P22: PB | Q22: amanda.gamorim@educacao.pe.gov.br | R22: 05739248485 | S22: SEDUC
A23: PCPE - Cargo 01: Agente de Policia - 2025.2 | B23: AP-07-2025.2 | C23: 2321 | D23: 2025-11-17 | E23: 10045686 | F23: AMANDA RAFAELA DE AZEVEDO SANTOS | G23: Destro | H23: 0 | J23: 0 | K23: 10233575421 | L23: 81988387265 | M23: f | N23: 8313208 | O23: 24072018 | P23: PE | Q23: amanda.rsantos@policiacivil.pe.gov.br | R23: 10233575421 | S23: PCPE
A24: PCPE - Cargo 01: Agente de Policia - 2025.2 | B24: AP-07-2025.2 | C24: 2191 | D24: 2025-11-17 | E24: 10005467 | F24: ANA CAROLINA DE SOUZA FRANCA | G24: Destro | H24: 0 | J24: 0 | K24: 7995582498 | L24: 87999499077 | M24: f | N24: 7987574 | O24: 27032023 | P24: SDS/PE | Q24: anac.franca@pm.pe.gov.br | R24: 07995582498 | S24: PM
A25: PCPE - Cargo 01: Agente de Policia - 2025.2 | B25: AP-08-2025.2 | C25: 2422 | D25: 2025-11-24 | E25: 10045297 | F25: ANA CLARA RODRIGUES ALVES | G25: Destro | H25: 0 | J25: 0 | K25: 12048136478 | L25: 87999468932 | M25: f | N25: 9724221 | O25: 22052013 | P25: SDS PE | Q25: ana.alves @pm.pe.gov.br | R25: 12048136478 | S25: PM
A26: PCPE - Cargo 01: Agente de Policia - 2025.2 | B26: AP-03-2025.2 | C26: 2523 | D26: 2025-12-05 | E26: 10065667 | F26: ANDERSON CARLOS ALBUQUERQUE DE SANTANA | G26: Destro | H26: 0 | J26: 0 | K26: 8272868482 | L26: 81999692158 | M26: m | N26: 7461557 | O26: 28032014 | P26: PE | Q26: anderson.santana@pm.pe.gov.br | R26: 08272868482 | S26: PM
A27: PCPE - Cargo 01: Agente de Policia - 2025.2 | B27: AP-02-2025.2 | C27: 2076 | D27: 2025-11-17 | E27: 10058967 | F27: ANDERSON LUIZ GOMES DE FREITAS TORRES | G27: Destro | H27: 0 | J27: 0 | K27: 9075675410 | L27: 81996466146 | M27: m | N27: 8297040 | O27: 15062017 | P27: PE | Q27: andersonluiz.freitas@policiacivil.pe.gov.br | R27: 09075675410 | S27: PCPE
... A42: PCPE - Cargo 01: Agente de Policia - 2025.2 | B42: AP-05-2025.2 | C42: 2268 | D42: 2025-11-17 | E42: 10055832 | F42: BIANCA PRISCILA GARCIA SILVA | G42: Destro | H42: 0 | J42: 0 | K42: 6706767484 | L42: 81979142121 | M42: f | N42: 8547175 | O42: 09042021 | P42: PE | Q42: bianca.garcia@policiacivil.pe.gov.br | R42: 06706767484 | S42: PCPE
A43: PCPE - Cargo 01: Agente de Policia - 2025.2 | B43: AP-05-2025.2 | C43: 2188 | D43: 2025-11-17 | E43: 10024927 | F43: BRUNA MARIA DA SILVA MARTINS | G43: Destro | H43: 1 | I43: Visão Monocular CID H54.4- SEM NECESSIDADES E ATENÇÕES ESPECIAIS | J43: 0 | K43: 70989600475 | L43: 81993968671 | M43: f | N43: 10043702 | O43: 13092024 | P43: PE | Q43: bruna.smartins@policiacivil.pe.gov.br | R43: 70989600475 | S43: PCPE
A44: PCPE - Cargo 01: Agente de Policia - 2025.2 | B44: AP-01-2025.2 | C44: 2096 | D44: 2025-11-17 | E44: 10043362 | F44: BRUNA MARIA SOBRAL | G44: Destro | H44: 0 | J44: 0 | K44: 10193217414 | L44: 81995108448 | M44: f | N44: 8375754 | O44: 23042024 | P44: PE | Q44: bruna.sobral@policiacivil.pe.gov.br | R44: 10193217414 | S44: PCPE
A45: PCPE - Cargo 01: Agente de Policia - 2025.2 | B45: AP-02-2025.2 | C45: 2274 | D45: 2025-11-17 | E45: 10038017 | F45: BRUNO EUGENIO PACELLI DE OLIVEIRA | G45: Destro | H45: 0 | J45: 0 | K45: 70189836490 | L45: 81973417093 | M45: m | N45: 9412122 | O45: 19012018 | P45: PE | Q45: bruno.pacelli@policiacivil.pe.gov.br | R45: 70189836490 | S45: PCPE
A46: PCPE - Cargo 01: Agente de Policia - 2025.2 | B46: AP-02-2025.2 | C46: 2365 | D46: 2025-11-18 | E46: 10067769 | F46: CAIO ALEXANDRE DE LIMA OLIVEIRA | G46: Destro | H46: 0 | J46: 0 | K46: 11146821441 | L46: 87991275540 | M46: m | N46: 8561806 | O46: 27122022 | P46: PE | Q46: caio.oliveira@pm.pe.gov.br | R46: 11146821441 | S46: PM
A47: PCPE - Cargo 01: Agente de Policia - 2025.2 | B47: AP-04-2025.2 | C47: 2289 | D47: 2025-11-17 | E47: 10041613 | F47: CAIO APOLO PEREIRA PASSOS | G47: Destro | H47: 0 | J47: 0 | K47: 9804078422 | L47: 79996866590 | M47: m | N47: 7839073 | O47: 11122012 | P47: PE | Q47: caioapolo.passos@policiacivil.pe.gov.br | R47: 09804078422 | S47: PCPE
A48: PCPE - Cargo 01: Agente de Policia - 2025.2 | B48: AP-05-2025.2 | C48: 2117 | D48: 2025-11-17 | E48: 10018639 | F48: CAMILA SOUZA PRIMO | G48: Destro | H48: 0 | J48: 0 | K48: 10622072463 | L48: 81998635304 | M48: f | N48: 9299333 | O48: 06012018 | P48: SDS/PE | Q48: camila.primo@policiacivil.pe.gov.br | R48: 10622072463 | S48: PCPE
A49: PCPE - Cargo 01: Agente de Policia - 2025.2 | B49: AP-06-2025.2 | C49: 2107 | D49: 2025-11-17 | E49: 10005965 | F49: CARLOS ALEXANDRE DOS SANTOS DIAS | G49: Destro | H49: 0 | J49: 0 | K49: 4305665492 | L49: 81997444853 | M49: m | N49: 5965532 | O49: 29101997 | P49: PE | Q49: carlos.dias@bombeiros.pe.gov.br | R49: 04305665492 | S49: BMPE
A50: PCPE - Cargo 01: Agente de Policia - 2025.2 | B50: AP-01-2025.2 | C50: 2423 | D50: 2025-11-24 | E50: 10009542 | F50: CARLOS ANDRE XAVIER DA SILVA | G50: Destro | H50: 0 | J50: 0 | K50: 6930737488 | L50: 81996361002 | M50: m | N50: 6372027 | O50: 08012010 | P50: PE | Q50: carlos.axs@policiacivil.pe.gov.br | R50: 06930737488 | S50: PCPE
A51: PCPE - Cargo 01: Agente de Policia - 2025.2 | B51: AP-04-2025.2 | C51: 2276 | D51: 2025-11-17 | E51: 10064876 | F51: CARLOS EDUARDO MARTINS NUNES CODECEIRA | G51: Destro | H51: 0 | J51: 0 | K51: 10777971410 | L51: 81981128814 | M51: m | N51: 8567974 | O51: 29122021 | P51: PE | Q51: carlos.codeceira@policiacivil.pe.gov.br | R51: 10777971410 | S51: PCPE
A52: PCPE - Cargo 01: Agente de Policia - 2025.2 | B52: AP-06-2025.2 | C52: 2233 | D52: 2025-11-17 | E52: 10046213 | F52: CAROLINA RODRIGUES MEDRADO | G52: Destro | H52: 0 | J52: 0 | K52: 5915874592 | L52: 8738617453 | M52: f | N52: 10685262 | O52: 29012021 | P52: PE | Q52: carolina.medrado@policiacivil.pe.gov.br | R52: 05915874592 | S52: PCPE
A53: PCPE - Cargo 01: Agente de Policia - 2025.2 | B53: AP-08-2025.2 | C53: 2046 | D53: 2025-11-17 | E53: 10001575 | F53: CESAR BATISTA ALENCAR PINTO | G53: Destro | H53: 0 | J53: 0 | K53: 9429256459 | L53: 081986333367 | M53: m | N53: 8789690 | O53: 25092025 | P53: PE | Q53: cesar.pinto@policiacivil.pe.gov.br | R53: 09429256459 | S53: PCPE
A54: PCPE - Cargo 01: Agente de Policia - 2025.2 | B54: AP-03-2025.2 | C54: 2114 | D54: 2025-11-17 | E54: 10067620 | F54: CLEBER FERREIRA MARQUES | G54: Destro | H54: 0 | J54: 0 | K54: 1065197519 | L54: 71992882944 | M54: m | N54: 2088848980 | O54: 01112023 | P54: DETRAN/BA | Q54: cleber.marques@policiacivil.pe.gov.br | R54: 01065197519 | S54: PCPE
...
